<?xml version="1.0" encoding="utf-8"?>
<!-- This URDF was automatically created by SolidWorks to URDF Exporter! Originally created by Stephen Brawner (brawner@gmail.com) 
     Commit Version: 1.6.0-4-g7f85cfe  Build Version: 1.6.7995.38578
     For more information, please see http://wiki.ros.org/sw_urdf_exporter -->
<robot
  name="Barco_Rc">
  <link
    name="base_link">
    <inertial>
      <origin
        xyz="-0.010526 -0.0088734 -0.053339"
        rpy="0 0 0" />
      <mass
        value="0.35537" />
      <inertia
        ixx="0.0015096"
        ixy="-2.0272E-09"
        ixz="9.8614E-06"
        iyy="0.0017758"
        iyz="7.4582E-05"
        izz="0.00043936" />
    </inertial>
    <visual>
      <origin
        xyz="0 0 0"
        rpy="0 0 0" />
      <geometry>
        <mesh
          filename="package://Barco_Rc/meshes/base_link.STL" />
      </geometry>
      <material
        name="">
        <color
          rgba="1 1 1 1" />
      </material>
    </visual>
    <collision>
      <origin
        xyz="0 0 0"
        rpy="0 0 0" />
      <geometry>
        <mesh
          filename="package://Barco_Rc/meshes/base_link.STL" />
      </geometry>
    </collision>
  </link>
  <link
    name="turbina_Link">
    <inertial>
      <origin
        xyz="0.030537 0.030447 0.51222"
        rpy="0 0 0" />
      <mass
        value="0.0081135" />
      <inertia
        ixx="1.4255E-06"
        ixy="-7.4299E-08"
        ixz="1.9933E-08"
        iyy="1.3243E-06"
        iyz="1.6642E-07"
        izz="1.9044E-06" />
    </inertial>
    <visual>
      <origin
        xyz="0 0 0"
        rpy="0 0 0" />
      <geometry>
        <mesh
          filename="package://Barco_Rc/meshes/turbina_Link.STL" />
      </geometry>
      <material
        name="">
        <color
          rgba="1 1 1 1" />
      </material>
    </visual>
    <collision>
      <origin
        xyz="0 0 0"
        rpy="0 0 0" />
      <geometry>
        <mesh
          filename="package://Barco_Rc/meshes/turbina_Link.STL" />
      </geometry>
    </collision>
  </link>
  <joint
    name="turbina_joint"
    type="fixed">
    <origin
      xyz="-0.041936 0.039764 0.35289"
      rpy="3.1416 -0.0012331 0" />
    <parent
      link="base_link" />
    <child
      link="turbina_Link" />
    <axis
      xyz="0 0 0" />
    <limit
      lower="0"
      upper="0"
      effort="0"
      velocity="0" />
  </joint>
  <link
    name="eje_Link">
    <inertial>
      <origin
        xyz="-1.4514E-07 2.1155E-07 -0.044615"
        rpy="0 0 0" />
      <mass
        value="0.0053392" />
      <inertia
        ixx="3.9696E-06"
        ixy="1.1539E-12"
        ixz="3.2636E-11"
        iyy="3.9696E-06"
        iyz="-4.7568E-11"
        izz="5.0584E-08" />
    </inertial>
    <visual>
      <origin
        xyz="0 0 0"
        rpy="0 0 0" />
      <geometry>
        <mesh
          filename="package://Barco_Rc/meshes/eje_Link.STL" />
      </geometry>
      <material
        name="">
        <color
          rgba="0.79216 0.81961 0.93333 1" />
      </material>
    </visual>
    <collision>
      <origin
        xyz="0 0 0"
        rpy="0 0 0" />
      <geometry>
        <mesh
          filename="package://Barco_Rc/meshes/eje_Link.STL" />
      </geometry>
    </collision>
  </link>
  <joint
    name="eje_joint"
    type="continuous">
    <origin
      xyz="-0.011109 0.011999 -0.027724"
      rpy="0 0 2.9071" />
    <parent
      link="base_link" />
    <child
      link="eje_Link" />
    <axis
      xyz="0 0 1" />
  </joint>
  <link
    name="helice_Link">
    <inertial>
      <origin
        xyz="1.1048E-08 3.5709E-09 -0.010081"
        rpy="0 0 0" />
      <mass
        value="0.00082267" />
      <inertia
        ixx="3.1321E-08"
        ixy="-1.1867E-11"
        ixz="-9.1333E-14"
        iyy="3.126E-08"
        iyz="-4.3503E-14"
        izz="3.083E-08" />
    </inertial>
    <visual>
      <origin
        xyz="0 0 0"
        rpy="0 0 0" />
      <geometry>
        <mesh
          filename="package://Barco_Rc/meshes/helice_Link.STL" />
      </geometry>
      <material
        name="">
        <color
          rgba="0.79216 0.81961 0.93333 1" />
      </material>
    </visual>
    <collision>
      <origin
        xyz="0 0 0"
        rpy="0 0 0" />
      <geometry>
        <mesh
          filename="package://Barco_Rc/meshes/helice_Link.STL" />
      </geometry>
    </collision>
  </link>
  <joint
    name="helice_joint"
    type="continuous">
    <origin
      xyz="-0.011109 0.011999 -0.12692"
      rpy="0 0 2.1217" />
    <parent
      link="base_link" />
    <child
      link="helice_Link" />
    <axis
      xyz="0 0 1" />
  </joint>
  <link
    name="motor_Link">
    <inertial>
      <origin
        xyz="2.2968E-07 0.0067932 -3.3477E-07"
        rpy="0 0 0" />
      <mass
        value="0.0082731" />
      <inertia
        ixx="6.3579E-07"
        ixy="-4.797E-11"
        ixz="1.7709E-10"
        iyy="6.8999E-07"
        iyz="6.9918E-11"
        izz="6.3565E-07" />
    </inertial>
    <visual>
      <origin
        xyz="0 0 0"
        rpy="0 0 0" />
      <geometry>
        <mesh
          filename="package://Barco_Rc/meshes/motor_Link.STL" />
      </geometry>
      <material
        name="">
        <color
          rgba="0.79216 0.81961 0.93333 1" />
      </material>
    </visual>
    <collision>
      <origin
        xyz="0 0 0"
        rpy="0 0 0" />
      <geometry>
        <mesh
          filename="package://Barco_Rc/meshes/motor_Link.STL" />
      </geometry>
    </collision>
  </link>
  <joint
    name="motor_joint"
    type="continuous">
    <origin
      xyz="-0.011109 0.011999 0"
      rpy="-1.5708 0 -0.23454" />
    <parent
      link="base_link" />
    <child
      link="motor_Link" />
    <axis
      xyz="0 1 0" />
  </joint>
</robot>